Workbook

Sheet 대시보드
A2: OpsLoop 프로젝트 진행 대시보드 (WBS v2.0)
A3: 2026.09.02(수) ~ 10.16(금) 마지막 갱신 기준: WBS 시트 실시간 연동
A5: 영역별 진행 현황 | J5: 기준 목록 · 입력과 색의 기준
A6: 영역 | B6: 구분 | C6: 담당 범위 | D6: 전체 작업 | E6: 완료 | F6: 진행중 | G6: 미착수 | H6: 완료율 | J6: 상태 | L6: 영역 | M6: 구분
A7: A | B7: 인프라 · 배포 | C7: 프로비저닝 · 망 분리 · 방화벽 · 이중화 | D7: =COUNTIFS(WBS!$D$5:$D$106,$A7,WBS!$L$5:$L$106,">0") | E7: =COUNTIFS(WBS!$D$5:$D$106,$A7,WBS!$F$5:$F$106,"완료") | F7: =COUNTIFS(WBS!$D$5:$D$106,$A7,WBS!$F$5:$F$106,"진행중") | G7: =COUNTIFS(WBS!$D$5:$D$106,$A7,WBS!$F$5:$F$106,"미착수") | H7: =IF($D7=0,"",$E7/$D7) | J7: 완료 | L7: A | M7: =B7
A8: B | B8: 수집 · 탐지 | C8: 로그 파이프라인 · 디코이 · 탐지 · 압축 | D8: =COUNTIFS(WBS!$D$5:$D$106,$A8,WBS!$L$5:$L$106,">0") | E8: =COUNTIFS(WBS!$D$5:$D$106,$A8,WBS!$F$5:$F$106,"완료") | F8: =COUNTIFS(WBS!$D$5:$D$106,$A8,WBS!$F$5:$F$106,"진행중") | G8: =COUNTIFS(WBS!$D$5:$D$106,$A8,WBS!$F$5:$F$106,"미착수") | H8: =IF($D8=0,"",$E8/$D8) | J8: 진행중 | L8: B | M8: =B8
A9: C | B9: 관제 콘솔 | C9: 화면 · 판정 · 대시보드 · 실시간 | D9: =COUNTIFS(WBS!$D$5:$D$106,$A9,WBS!$L$5:$L$106,">0") | E9: =COUNTIFS(WBS!$D$5:$D$106,$A9,WBS!$F$5:$F$106,"완료") | F9: =COUNTIFS(WBS!$D$5:$D$106,$A9,WBS!$F$5:$F$106,"진행중") | G9: =COUNTIFS(WBS!$D$5:$D$106,$A9,WBS!$F$5:$F$106,"미착수") | H9: =IF($D9=0,"",$E9/$D9) | J9: 미착수 | L9: C | M9: =B9
A10: D | B10: 분석 · 운영 | C10: 정상 트래픽 · 폐루프 · 리플레이 · 지표 | D10: =COUNTIFS(WBS!$D$5:$D$106,$A10,WBS!$L$5:$L$106,">0") | E10: =COUNTIFS(WBS!$D$5:$D$106,$A10,WBS!$F$5:$F$106,"완료") | F10: =COUNTIFS(WBS!$D$5:$D$106,$A10,WBS!$F$5:$F$106,"진행중") | G10: =COUNTIFS(WBS!$D$5:$D$106,$A10,WBS!$F$5:$F$106,"미착수") | H10: =IF($D10=0,"",$E10/$D10) | J10: 지연 | L10: D | M10: =B10
A11: - | B11: 공통 · 문서 | C11: 기획 · 테스트 · 산출물 문서화 | D11: =COUNTIFS(WBS!$D$5:$D$106,$A11,WBS!$L$5:$L$106,">0") | E11: =COUNTIFS(WBS!$D$5:$D$106,$A11,WBS!$F$5:$F$106,"완료") | F11: =COUNTIFS(WBS!$D$5:$D$106,$A11,WBS!$F$5:$F$106,"진행중") | G11: =COUNTIFS(WBS!$D$5:$D$106,$A11,WBS!$F$5:$F$106,"미착수") | H11: =IF($D11=0,"",$E11/$D11) | L11: - | M11: =B11
A12: 전체 | D12: =COUNTIFS(WBS!$L$5:$L$106,">0") | E12: =COUNTIF(WBS!$F$5:$F$106,"완료") | F12: =COUNTIF(WBS!$F$5:$F$106,"진행중") | G12: =COUNTIF(WBS!$F$5:$F$106,"미착수") | H12: =IF($D12=0,"",$E12/$D12)
J13: 목록을 고치면 WBS 드롭다운과 색이 함께 바뀝니다
A14: 임계경로(★) 작업 현황
A15: 상태 | B15: 건수 | J15: 오늘 기준
A16: 미착수 | B16: =COUNTIFS(WBS!$K$5:$K$106,"★",WBS!$F$5:$F$106,"미착수") | J16: 종료일 지난 미완료 | M16: =COUNTIFS(WBS!$L$5:$L$106,">0",WBS!$H$5:$H$106,"<"&TODAY(),WBS!$F$5:$F$106,"<>완료")
A17: 진행중 | B17: =COUNTIFS(WBS!$K$5:$K$106,"★",WBS!$F$5:$F$106,"진행중") | J17: 7일 안에 끝날 작업 | M17: =COUNTIFS(WBS!$L$5:$L$106,">0",WBS!$H$5:$H$106,">="&TODAY(),WBS!$H$5:$H$106,"<"&TODAY()+7,WBS!$F$5:$F$106,"<>완료")
A18: 완료 | B18: =COUNTIFS(WBS!$K$5:$K$106,"★",WBS!$F$5:$F$106,"완료") | J18: 오늘 | M18: =TODAY()
A19: 지연 | B19: =COUNTIFS(WBS!$K$5:$K$106,"★",WBS!$F$5:$F$106,"지연")
A21: 단계별 진행 현황
A22: 단계 | B22: 전체 | C22: 완료 | D22: 완료율
A23: 기획 | B23: =COUNTIFS(WBS!$B$5:$B$106,"기획",WBS!$L$5:$L$106,">0") | C23: =COUNTIFS(WBS!$B$5:$B$106,"기획",WBS!$F$5:$F$106,"완료") | D23: =IF($B23=0,"",$C23/$B23)
A24: 설계 | B24: =COUNTIFS(WBS!$B$5:$B$106,"설계",WBS!$L$5:$L$106,">0") | C24: =COUNTIFS(WBS!$B$5:$B$106,"설계",WBS!$F$5:$F$106,"완료") | D24: =IF($B24=0,"",$C24/$B24)
A25: 개발 | B25: =COUNTIFS(WBS!$B$5:$B$106,"개발",WBS!$L$5:$L$106,">0") | C25: =COUNTIFS(WBS!$B$5:$B$106,"개발",WBS!$F$5:$F$106,"완료") | D25: =IF($B25=0,"",$C25/$B25)
A26: 테스트 | B26: =COUNTIFS(WBS!$B$5:$B$106,"테스트",WBS!$L$5:$L$106,">0") | C26: =COUNTIFS(WBS!$B$5:$B$106,"테스트",WBS!$F$5:$F$106,"완료") | D26: =IF($B26=0,"",$C26/$B26)
A27: 문서화 | B27: =COUNTIFS(WBS!$B$5:$B$106,"문서화",WBS!$L$5:$L$106,">0") | C27: =COUNTIFS(WBS!$B$5:$B$106,"문서화",WBS!$F$5:$F$106,"완료") | D27: =IF($B27=0,"",$C27/$B27)
A28: 발표 | B28: =COUNTIFS(WBS!$B$5:$B$106,"발표",WBS!$L$5:$L$106,">0") | C28: =COUNTIFS(WBS!$B$5:$B$106,"발표",WBS!$F$5:$F$106,"완료") | D28: =IF($B28=0,"",$C28/$B28)
A30: 상태 값은 WBS 시트에서만 변경하세요. 이 시트의 모든 수치는 자동 집계됩니다.

Sheet 간트차트
A1: 간트차트 (2026.09.02 ~ 10.16) — OpsLoop
A2: ※ WBS 시트의 작업명 · 담당 · 날짜 · 상태와 실시간 연동됩니다. 이 시트는 직접 수정하지 마세요.
A4: WBS ID | B4: 작업명 | C4: 영역 | D4: 46267 | E4: 46268 | F4: 46269 | G4: 46270 | H4: 46271 | I4: 46272 | J4: 46273 | K4: 46274 | L4: 46275 | M4: 46276 | N4: 46277 | O4: 46278 | P4: 46279 | Q4: 46280 | R4: 46281 | S4: 46282 | T4: 46283 | U4: 46284 | V4: 46285 | W4: 46286 | X4: 46287 | Y4: 46288 | Z4: 46289 | AA4: 46290 | AB4: 46291 | AC4: 46292 | AD4: 46293 | AE4: 46294 | AF4: 46295 | AG4: 46296 | AH4: 46297 | AI4: 46298 | AJ4: 46299 | AK4: 46300 | AL4: 46301 | AM4: 46302 | AN4: 46303 | AO4: 46304 | AP4: 46305 | AQ4: 46306 | AR4: 46307 | AS4: 46308 | AT4: 46309 | AU4: 46310 | AV4: 46311 | AX4: 시작 | AY4: 종료 | AZ4: 상태
D5: 수 | E5: 목 | F5: 금 | G5: 토 | H5: 일 | I5: 월 | J5: 화 | K5: 수 | L5: 목 | M5: 금 | N5: 토 | O5: 일 | P5: 월 | Q5: 화 | R5: 수 | S5: 목 | T5: 금 | U5: 토 | V5: 일 | W5: 월 | X5: 화 | Y5: 수 | Z5: 목 | AA5: 금 | AB5: 토 | AC5: 일 | AD5: 월 | AE5: 화 | AF5: 수 | AG5: 목 | AH5: 금 | AI5: 토 | AJ5: 일 | AK5: 월 | AL5: 화 | AM5: 수 | AN5: 목 | AO5: 금 | AP5: 토 | AQ5: 일 | AR5: 월 | AS5: 화 | AT5: 수 | AU5: 목 | AV5: 금
A6: 1.1 | B6: =WBS!C6 | C6: =WBS!D6 | AX6: =WBS!G6 | AY6: =WBS!H6 | AZ6: =WBS!F6
A7: 1.2 | B7: =WBS!C7 | C7: =WBS!D7 | AX7: =WBS!G7 | AY7: =WBS!H7 | AZ7: =WBS!F7
A8: 1.3 | B8: =WBS!C8 | C8: =WBS!D8 | AX8: =WBS!G8 | AY8: =WBS!H8 | AZ8: =WBS!F8
A9: 1.4 | B9: =WBS!C9 | C9: =WBS!D9 | AX9: =WBS!G9 | AY9: =WBS!H9 | AZ9: =WBS!F9
A10: 1.5 | B10: =WBS!C10 | C10: =WBS!D10 | AX10: =WBS!G10 | AY10: =WBS!H10 | AZ10: =WBS!F10
A11: 1.6 | B11: =WBS!C11 | C11: =WBS!D11 | AX11: =WBS!G11 | AY11: =WBS!H11 | AZ11: =WBS!F11
A12: 1.7 | B12: =WBS!C12 | C12: =WBS!D12 | AX12: =WBS!G12 | AY12: =WBS!H12 | AZ12: =WBS!F12
A13: 2.0 | B13: =WBS!C13 | C13: =WBS!D13 | AX13: =WBS!G13 | AY13: =WBS!H13 | AZ13: =WBS!F13
A14: 2.1 | B14: =WBS!C14 | C14: =WBS!D14 | AX14: =WBS!G14 | AY14: =WBS!H14 | AZ14: =WBS!F14
A15: 2.2 | B15: =WBS!C15 | C15: =WBS!D15 | AX15: =WBS!G15 | AY15: =WBS!H15 | AZ15: =WBS!F15
A16: 2.3 | B16: =WBS!C16 | C16: =WBS!D16 | AX16: =WBS!G16 | AY16: =WBS!H16 | AZ16: =WBS!F16
A17: 2.4 | B17: =WBS!C17 | C17: =WBS!D17 | AX17: =WBS!G17 | AY17: =WBS!H17 | AZ17: =WBS!F17
... A97: 6.3 | B97: =WBS!C97 | C97: =WBS!D97 | AX97: =WBS!G97 | AY97: =WBS!H97 | AZ97: =WBS!F97
B104: 범례 | E104: 완료 | J104: 진행중 | O104: 미착수 | T104: 지연 | Y104: 주말 | AD104: 오늘
A105: ★ (WBS ID 빨간 글씨) = 임계경로. 담당 · 날짜 · 상태는 WBS 시트 기준 자동 동기화됩니다.

Sheet WBS
A1: 2026 파이널 프로젝트 WBS v2.0 — OpsLoop (실시간 위협 탐지·대응 관제 플랫폼)
A2: 기간: 2026.09.02(수) ~ 10.16(금) | 1인 프로젝트 | 2차 피드백 반영 개정 (2026.09.18) · 화면 설계 반영 (2026.09.19) · 연구소장 피드백 반영 (2026.09.22) | 매 주차 종료 시점 시연 가능 상태 유지
A4: WBS ID | B4: 구분 | C4: 작업명 | D4: 영역 | E4: 담당 | F4: 상태 | G4: 시작 | H4: 종료 | I4: 기간(일) | J4: 산출물 | K4: 임계경로 | L4: 레벨
A5: 1.0 | B5: 기획 | C5: [기획 단계] | L5: 0
A6: 1.1 | B6: 기획 | C6: 주제 확정 및 1차 계획서 작성 | D6: - | E6: 한성민 | F6: 완료 | G6: 46259 | H6: 46266 | I6: =IF(AND(G6<>"",H6<>""),H6-G6+1,"") | J6: 1차 계획서·요약 PPT | K6: ★ | L6: 1
A7: 1.2 | B7: 기획 | C7: 요구사항 정의 · 우선순위 3계층 확정 | D7: - | E7: 한성민 | F7: 완료 | G7: 46264 | H7: 46266 | I7: =IF(AND(G7<>"",H7<>""),H7-G7+1,"") | J7: 서비스 기능 정의서(초안) | K7: ★ | L7: 1
A8: 1.3 | B8: 기획 | C8: WBS v1.0 작성 및 산출물 체계 확정 | D8: - | E8: 한성민 | F8: 완료 | G8: 46267 | H8: 46267 | I8: =IF(AND(G8<>"",H8<>""),H8-G8+1,"") | J8: WBS | K8: ★ | L8: 1
A9: 1.4 | B9: 기획 | C9: 프로젝트 요약서(4장) 작성 및 제출 | D9: - | E9: 한성민 | F9: 완료 | G9: 46281 | H9: 46282 | I9: =IF(AND(G9<>"",H9<>""),H9-G9+1,"") | J9: 프로젝트 요약서 | K9: ★ | L9: 1
A10: 1.5 | B10: 기획 | C10: 2차 피드백 반영 방향 확정 (디코이 · 관문 방화벽 · 가상화) | D10: - | E10: 한성민 | F10: 완료 | G10: 46282 | H10: 46283 | I10: =IF(AND(G10<>"",H10<>""),H10-G10+1,"") | J10: 계획 개정 문서 | K10: ★ | L10: 1
A11: 1.6 | B11: 기획 | C11: 범위 재조정 — 삭제 · 연기 항목 확정 (WBS v2.0) | D11: - | E11: 한성민 | F11: 완료 | G11: 46283 | H11: 46284 | I11: =IF(AND(G11<>"",H11<>""),H11-G11+1,"") | J11: WBS v2.0 | K11: ★ | L11: 1
A12: 1.7 | B12: 기획 | C12: 상시 가동 서버 가용성 확인 → 전개 방식 확정 (클라우드 DMZ + 가상화 내부망) | D12: A | E12: 한성민 | F12: 완료 | G12: 46283 | H12: 46284 | I12: =IF(AND(G12<>"",H12<>""),H12-G12+1,"") | J12: 아키텍처 결정 기록 | K12: ★ | L12: 1
A13: 2.0 | B13: 설계 | C13: [설계 단계] | L13: 0
A14: 2.1 | B14: 설계 | C14: 공통 로그 스키마 확정 (전 파이프라인의 전제) | D14: B | E14: 한성민 | F14: 완료 | G14: 46268 | H14: 46270 | I14: =IF(AND(G14<>"",H14<>""),H14-G14+1,"") | J14: API 스펙 문서 | K14: ★ | L14: 1
A15: 2.2 | B15: 설계 | C15: 데이터 모델링 (규칙 · 인시던트 · 판정 · 차단 · 노드) | D15: B | E15: 한성민 | F15: 완료 | G15: 46269 | H15: 46285 | I15: =IF(AND(G15<>"",H15<>""),H15-G15+1,"") | J15: 테이블 정의서 | K15: ★ | L15: 1
A16: 2.3 | B16: 설계 | C16: 인시던트 판정 기준 확정 (실제위협·무시가능·오탐) | D16: D | E16: 한성민 | F16: 완료 | G16: 46270 | H16: 46271 | I16: =IF(AND(G16<>"",H16<>""),H16-G16+1,"") | J16: 판정 기준 문서 | K16: ★ | L16: 1
A17: 2.4 | B17: 설계 | C17: 탐지 평가 함수 인터페이스 설계 (규칙버전 · 시간구간 인자) | D17: B | E17: 한성민 | F17: 완료 | G17: 46271 | H17: 46272 | I17: =IF(AND(G17<>"",H17<>""),H17-G17+1,"") | J17: 프로그램 설계서 | K17: ★ | L17: 1
A18: 2.5 | B18: 설계 | C18: 하이브리드 네트워크 설계 (대역 · 경로 · 방화벽 규칙표) | D18: A | E18: 한성민 | F18: 완료 | G18: 46283 | H18: 46285 | I18: =IF(AND(G18<>"",H18<>""),H18-G18+1,"") | J18: 네트워크 설계서 | K18: ★ | L18: 1
A19: 2.6 | B19: 설계 | C19: 서버 · 네트워크 구성도 v6 (AWS DMZ + 온프레미스) | D19: A | E19: 한성민 | F19: 완료 | G19: 46285 | H19: 46286 | I19: =IF(AND(G19<>"",H19<>""),H19-G19+1,"") | J19: 시스템 구성도 | K19: ★ | L19: 1
A20: 2.7 | B20: 설계 | C20: 웹 디코이 설계 (콘솔과 동일한 인증 로그 형식) | D20: B | E20: 한성민 | F20: 완료 | G20: 46284 | H20: 46285 | I20: =IF(AND(G20<>"",H20<>""),H20-G20+1,"") | J20: 프로그램 설계서 | K20: ★ | L20: 1
A21: 2.8 | B21: 설계 | C21: 화면 설계 (인시던트 목록 · 상세 · 판정 · 대시보드) | D21: C | E21: 한성민 | F21: 완료 | G21: 46284 | H21: 46286 | I21: =IF(AND(G21<>"",H21<>""),H21-G21+1,"") | J21: 화면설계서 | K21: ★ | L21: 1
A22: 2.9 | B22: 설계 | C22: 전체 구성도 · 역할 분담도 개정 | D22: - | E22: 한성민 | F22: 완료 | G22: 46288 | H22: 46288 | I22: =IF(AND(G22<>"",H22<>""),H22-G22+1,"") | J22: 시스템 구성도 | L22: 1
A23: 3.0 | B23: 개발 | C23: [개발 단계] | L23: 0
A24: 3.1 | B24: 개발 | C24: [A] AWS DMZ 재구성 | D24: A | E24: 한성민 | F24: 진행중 | G24: 46288 | H24: 46294 | I24: =IF(AND(G24<>"",H24<>""),H24-G24+1,"") | J24: 인프라 코드 | K24: ★ | L24: 1
A25: 3.1.1 | C25: ▸ VPC · 서브넷 · 라우팅 Terraform 정의 | D25: A | E25: 한성민 | F25: 완료 | G25: 46287 | H25: 46288 | I25: =IF(AND(G25<>"",H25<>""),H25-G25+1,"") | J25: 인프라 코드 | K25: ★ | L25: 2
A26: 3.1.2 | C26: ▸ 관문 방화벽 인스턴스 (포트 전달 · 차단 로그 · SSM 전용 엔드포인트 · DMZ 유출 전면 차단) | D26: A | E26: 한성민 | F26: 완료 | G26: 46287 | H26: 46288 | I26: =IF(AND(G26<>"",H26<>""),H26-G26+1,"") | J26: 인프라 코드 · 방화벽 규칙 | K26: ★ | L26: 2
A27: 3.1.3 | C27: ▸ 허니팟 사설 서브넷 이전 (이미지 전 비밀 검사 · 로그 승계) | D27: A | E27: 한성민 | F27: 완료 | G27: 46288 | H27: 46288 | I27: =IF(AND(G27<>"",H27<>""),H27-G27+1,"") | J27: 이전 기록 | K27: ★ | L27: 2
A28: 3.1.4 | C28: ▸ 노드별 S3 쓰기 경계 · 관문 별도 역할 · DB 역할 최소 권한 (슈퍼유저 제거) | D28: A | E28: 한성민 | F28: 완료 | G28: 46288 | H28: 46289 | I28: =IF(AND(G28<>"",H28<>""),H28-G28+1,"") | J28: 인프라 코드 · DB 역할 정의 | K28: ★ | L28: 2
A29: 3.1.5 | C29: ▸ 구 앱 노드 정리 · 기간 비용 재확인 | D29: A | E29: 한성민 | F29: 진행중 | G29: 46290 | H29: 46294 | I29: =IF(AND(G29<>"",H29<>""),H29-G29+1,"") | J29: 비용 산정표 | L29: 2
A30: 3.2 | B30: 개발 | C30: [B] 웹 디코이 (선행 노출로 수집 시간 확보) | D30: B | E30: 한성민 | F30: 완료 | G30: 46284 | H30: 46291 | I30: =IF(AND(G30<>"",H30<>""),H30-G30+1,"") | J30: 소스코드 | K30: ★ | L30: 1
A31: 3.2.1 | C31: ▸ 가짜 admin 로그인 · 행위 기록 구현 | D31: B | E31: 한성민 | F31: 완료 | G31: 46284 | H31: 46286 | I31: =IF(AND(G31<>"",H31<>""),H31-G31+1,"") | J31: 소스코드 | K31: ★ | L31: 2
A32: 3.2.2 | C32: ▸ 현행 환경에 선행 노출 및 수집 시작 | D32: B | E32: 한성민 | F32: 완료 | G32: 46286 | H32: 46287 | I32: =IF(AND(G32<>"",H32<>""),H32-G32+1,"") | J32: 수집 로그 | K32: ★ | L32: 2
A33: 3.2.3 | C33: ▸ 디코이 로그 정규화 (공통 스키마 편입) | D33: B | E33: 한성민 | F33: 완료 | G33: 46289 | H33: 46291 | I33: =IF(AND(G33<>"",H33<>""),H33-G33+1,"") | J33: 소스코드 | L33: 2
A34: 3.3 | B34: 개발 | C34: [A] 온프레미스 내부망 구축 (가상화) | D34: A | E34: 한성민 | F34: 완료 | G34: 46287 | H34: 46293 | I34: =IF(AND(G34<>"",H34<>""),H34-G34+1,"") | J34: 배포 환경 | K34: ★ | L34: 1
A35: 3.3.1 | C35: ▸ VM 5대 생성 (보호 대상 시험 서버 web-01 포함) · 가상 스위치로 세그먼트 분리 | D35: A | E35: 한성민 | F35: 완료 | G35: 46287 | H35: 46289 | I35: =IF(AND(G35<>"",H35<>""),H35-G35+1,"") | J35: 배포 환경 | K35: ★ | L35: 2
A36: 3.3.2 | C36: ▸ 내부 방화벽 규칙 적용 및 통신 검증 | D36: A | E36: 한성민 | F36: 완료 | G36: 46289 | H36: 46290 | I36: =IF(AND(G36<>"",H36<>""),H36-G36+1,"") | J36: 방화벽 규칙표 | K36: ★ | L36: 2
A37: 3.3.3 | C37: ▸ HAProxy 구성 (콘솔 A · B 분배) | D37: A | E37: 한성민 | F37: 완료 | G37: 46290 | H37: 46291 | I37: =IF(AND(G37<>"",H37<>""),H37-G37+1,"") | J37: 설정 파일 | L37: 2
A38: 3.3.4 | C38: ▸ 데이터베이스 · 애플리케이션 이전 | D38: A | E38: 한성민 | F38: 완료 | G38: 46291 | H38: 46293 | I38: =IF(AND(G38<>"",H38<>""),H38-G38+1,"") | J38: 이전 검증 기록 | K38: ★ | L38: 2
A39: 3.3.5 | C39: ▸ 관리망 VPN (Tailscale · WireGuard 기반) · 모바일 접속 | D39: A | E39: 한성민 | F39: 완료 | G39: 46292 | H39: 46293 | I39: =IF(AND(G39<>"",H39<>""),H39-G39+1,"") | J39: 설정 파일 | L39: 2
A40: 3.4 | B40: 개발 | C40: [B] 수집 파이프라인 | D40: B | E40: 한성민 | F40: 완료 | G40: 46286 | H40: 46288 | I40: =IF(AND(G40<>"",H40<>""),H40-G40+1,"") | J40: 소스코드 | K40: ★ | L40: 1
A41: 3.4.1 | C41: ▸ S3 가져오기 · 소급 적재 | D41: B | E41: 한성민 | F41: 완료 | G41: 46286 | H41: 46288 | I41: =IF(AND(G41<>"",H41<>""),H41-G41+1,"") | J41: 소스코드 | K41: ★ | L41: 2
...

Sheet 산출물 체크리스트
A1: 산출물 체크리스트 — OpsLoop (최종 제출 2026.10.16)
A2: ※ WBS 시트의 작업명 · 담당 · 날짜 · 상태와 실시간 연동됩니다. 상태는 WBS에서 변경하세요.
A4: No | B4: 산출물 | C4: 관련 WBS | D4: 영역 | E4: 작성 시작 | F4: 완료 목표 | G4: 제출 형식 | H4: 상태
A5: 1 | B5: =WBS!C78 | C5: 5.1 | D5: =WBS!D78 | E5: =WBS!G78 | F5: =WBS!H78 | G5: xlsx | H5: =WBS!F78
A6: 2 | B6: =WBS!C79 | C6: 5.2 | D6: =WBS!D79 | E6: =WBS!G79 | F6: =WBS!H79 | G6: pdf | H6: =WBS!F79
A7: 3 | B7: =WBS!C80 | C7: 5.3 | D7: =WBS!D80 | E7: =WBS!G80 | F7: =WBS!H80 | G7: pdf | H7: =WBS!F80
A8: 4 | B8: =WBS!C81 | C8: 5.4 | D8: =WBS!D81 | E8: =WBS!G81 | F8: =WBS!H81 | G8: pdf | H8: =WBS!F81
A9: 5 | B9: =WBS!C82 | C9: 5.5 | D9: =WBS!D82 | E9: =WBS!G82 | F9: =WBS!H82 | G9: pdf | H9: =WBS!F82
A10: 6 | B10: =WBS!C83 | C10: 5.6 | D10: =WBS!D83 | E10: =WBS!G83 | F10: =WBS!H83 | G10: pdf | H10: =WBS!F83
A11: 7 | B11: =WBS!C84 | C11: 5.7 | D11: =WBS!D84 | E11: =WBS!G84 | F11: =WBS!H84 | G11: pdf | H11: =WBS!F84
A12: 8 | B12: =WBS!C85 | C12: 5.8 | D12: =WBS!D85 | E12: =WBS!G85 | F12: =WBS!H85 | G12: pdf | H12: =WBS!F85
A13: 9 | B13: =WBS!C86 | C13: 5.9 | D13: =WBS!D86 | E13: =WBS!G86 | F13: =WBS!H86 | G13: pdf | H13: =WBS!F86
A14: 10 | B14: =WBS!C87 | C14: 5.10 | D14: =WBS!D87 | E14: =WBS!G87 | F14: =WBS!H87 | G14: pdf | H14: =WBS!F87
A15: 11 | B15: =WBS!C88 | C15: 5.11 | D15: =WBS!D88 | E15: =WBS!G88 | F15: =WBS!H88 | G15: pdf | H15: =WBS!F88
A16: 12 | B16: =WBS!C89 | C16: 5.12 | D16: =WBS!D89 | E16: =WBS!G89 | F16: =WBS!H89 | G16: pdf | H16: =WBS!F89
... A20: 16 | B20: =WBS!C93 | C20: 5.16 | D20: =WBS!D93 | E20: =WBS!G93 | F20: =WBS!H93 | G20: pdf | H20: =WBS!F93
A24: 총 16종. 제출 형식은 학과 지침에 맞춰 조정하세요. (v1.0 대비: CI/CD 산출물과 주간 보고서 자동 생성 제외, 네트워크 설계서 신설)
A25: 코드·설정 파일은 저장소(GitHub)로 제출하고, 소스코드 산출물은 주요 모듈을 PDF로 정리합니다.
